Workbook

Sheet DOE Status
B1: Details | D1: Merlin | H1: SM3.5 | L1: Percentage Pass Unit
A2: WW13 | C2: MSN | D2: Unit 1 | E2: Unit 2 | F2: Unit 3 | G2: =_xlfn.TEXTBEFORE(D2, " ", 1) & " 4" -> Unit 4 | H2: Unit 1 | I2: Unit 2 | J2: Unit 3 | K2: =_xlfn.TEXTBEFORE(H2, " ", 1) & " 4" -> Unit 4 | L2: =COUNTIF(H8:K8,"Pass")*25% -> 0.75
B3: PIN TO PIN | C3: 56A30400 | D3: Pass | E3: Pass | F3: Pass | G3: Damage | H3: Pass | I3: Pass | J3: Pass | K3: Damage
B4: IDD | D4: Pass | E4: Pass | F4: Pass | G4: Damage | H4: Pass | I4: Pass | J4: Pass | K4: Damage
B5: CONTINUITY | D5: Pass | E5: Pass | F5: Pass | G5: Damage | H5: Pass | I5: Pass | J5: Pass | K5: Damage
B6: FID | D6: Pass | E6: Pass | F6: Pass | G6: Damage | H6: Pass | I6: Pass | J6: Pass | K6: Damage
B7: HSRT FLOW | H7: Pass | I7: Pass | J7: Pass | K7: Damage
B8: STATUS UNIT | D8: Pass | E8: Pass | F8: Pass | G8: Damage | H8: Pass | I8: Pass | J8: Pass | K8: Damage
B9: REMARK
A11: ww13 | C11: MSN | D11: Unit 1 | E11: Unit 2 | F11: Unit 3 | G11: =_xlfn.TEXTBEFORE(D11, " ", 1) & " 4" -> Unit 4 | H11: Unit 1 | I11: Unit 2 | J11: Unit 3 | K11: =_xlfn.TEXTBEFORE(H11, " ", 1) & " 4" -> Unit 4 | L11: =COUNTIF(H17:K17,"Pass")*25% -> 0.75
B12: PIN TO PIN | C12: 56A08BF1 | D12: Pass | E12: Pass | F12: Pass | G12: Pass | H12: Pass | I12: Pass | J12: Pass | K12: Fail
B13: IDD | D13: Pass | E13: Pass | F13: Pass | G13: Pass | H13: Pass | I13: Pass | J13: Pass | K13: Fail
B14: CONTINUITY | D14: Pass | E14: Pass | F14: Pass | G14: Pass | H14: Pass | I14: Pass | J14: Pass | K14: Fail
B15: FID | D15: Pass | E15: Pass | F15: Pass | G15: Fail | H15: Pass | I15: Pass | J15: Pass | K15: Fail
B16: HSRT FLOW | H16: Pass | I16: Pass | J16: Fail | K16: Fail
B17: STATUS UNIT | D17: Pass | E17: Pass | F17: Pass | G17: Fail | H17: Pass | I17: Pass | J17: Pass | K17: Fail
B18: REMARK | G18: VDDQc lamped error | J18: Failed at HSRT Test , need to rework | K18: VDDQc lamped error
A20: ww13 | C20: MSN | D20: Unit 1 | E20: Unit 2 | F20: Unit 3 (GM) | G20: Unit 4 (GM) | H20: Unit 1 | I20: Unit 2 | J20: Unit 3 (GM) | K20: Unit 4 (GM) | L20: =COUNTIF(H26:K26,"Pass")*25% -> 0.75
B21: PIN TO PIN | C21: 56A079D4 | D21: Pass | E21: Pass | F21: Pass | G21: Damage | H21: Pass | I21: Pass | J21: Pass | K21: Damage
B22: IDD | D22: Pass | E22: Pass | F22: Pass | G22: Damage | H22: Pass | I22: Pass | J22: Pass | K22: Damage
B23: CONTINUITY | D23: Pass | E23: Pass | F23: Pass | G23: Damage | H23: Pass | I23: Pass | J23: Pass | K23: Damage
B24: FID | D24: Pass | E24: Pass | F24: Pass | G24: Damage | H24: Pass | I24: Pass | J24: Pass | K24: Damage
B25: HSRT FLOW | H25: Pass | I25: Pass | J25: Pass | K25: Damage
B26: STATUS UNIT | D26: Pass | E26: Pass | F26: Pass | G26: Damage | H26: Pass | I26: Pass | J26: Pass | K26: Damage
B27: REMARK
A29: WW13 | C29: MSN | D29: Unit 1 | E29: Unit 2 | F29: Unit 3 | G29: =_xlfn.TEXTBEFORE(D29, " ", 1) & " 4" -> Unit 4 | H29: Unit 1 | I29: Unit 2 | J29: Unit 3 | K29: =_xlfn.TEXTBEFORE(H29, " ", 1) & " 4" -> Unit 4 | L29: =COUNTIF(H35:K35,"Pass")*25% -> 0
B30: PIN TO PIN | C30: 56A079A4 | D30: Damage | E30: Pass | F30: Fail | G30: Pass | H30: Damage | I30: Fail | J30: Fail | K30: Fail
B31: IDD | D31: Damage | E31: Pass | F31: Pass | G31: Pass | H31: Damage | I31: Fail | J31: Fail | K31: Fail
B32: CONTINUITY | D32: Damage | E32: Pass | F32: Fail | G32: Pass | H32: Damage | I32: Fail | J32: Fail | K32: Fail
B33: FID | D33: Damage | E33: Fail | F33: Pass | G33: Fail | H33: Damage | I33: Fail | J33: Fail | K33: Fail
B34: HSRT FLOW | H34: Damage | I34: Fail | J34: Fail | K34: Fail
B35: STATUS UNIT | D35: Damage | E35: Fail | F35: Fail | G35: Fail | H35: Damage | I35: Fail | J35: Fail | K35: Fail
B36: REMARK | E36: VDDQc lamped error | F36: VDDQc lamped error | G36: VDDQc lamped error | I36: VDDQc lamped error | J36: VDDQc lamped error | K36: VDDQc lamped error
A38: ww14 | C38: MSN | D38: Unit 1 | E38: Unit 2 | F38: Unit 3 | G38: =_xlfn.TEXTBEFORE(D38, " ", 1) & " 4" -> Unit 4 | H38: Unit 1 | I38: Unit 2 | J38: Unit 3 | K38: =_xlfn.TEXTBEFORE(H38, " ", 1) & " 4" -> Unit 4 | L38: =COUNTIF(H44:K44,"Pass")*25% -> 0.5
B39: PIN TO PIN | C39: 569F1C57 | D39: Pass | E39: Pass | F39: Damage | G39: Damage | H39: Pass | I39: Pass | J39: Damage | K39: Damage
B40: IDD | D40: Pass | E40: Pass | F40: Damage | G40: Damage | H40: Pass | I40: Pass | J40: Damage | K40: Damage
B41: CONTINUITY | D41: Pass | E41: Pass | F41: Damage | G41: Damage | H41: Pass | I41: Pass | J41: Damage | K41: Damage
B42: FID | D42: Pass | E42: Pass | F42: Damage | G42: Damage | H42: Pass | I42: Pass | J42: Damage | K42: Damage
B43: HSRT FLOW | H43: Pass | I43: Pass | J43: Damage | K43: Damage
B44: STATUS UNIT | D44: Pass | E44: Pass | F44: Damage | G44: Damage | H44: Pass | I44: Pass | J44: Damage | K44: Damage
...

Sheet Summary_SM3.5
A1: SOCAMM DOE Summary – Result (Auto Calculation)
A3: Metric | B3: Count | C3: % (of tested) | D3: Notes
A4: Total MSN (non-empty) | B4: 48 | D4: MSN x 4 units per MSN
A5: Total unit done test (Pass+Fail+Damage) | B5: =B6+B7+B8 -> 77 | D5: Uses SM3.5 STATUS UNIT columns (G-J)
A6: Passed | B6: =SUMPRODUCT(--('DOE Status'!$B$1:$B$2001="STATUS UNIT"),--('DOE Status'!$H$1:$H$2001="Pass"))+SUMPRODUCT(--('DOE Status'!$B$1:$B$2001="STATUS UNIT"),--('DOE Status'!$I$1:$I$2001="Pass"))+SUMPRODUCT(--('DOE Status'!$B$1:$B$2001="STATUS UNIT"),--('DOE Status'!$J$1:$J$2001="Pass"))+SUMPRODUCT(--('DOE Status'!$B$1:$B$2001="STATUS UNIT"),--('DOE Status'!$K$1:$K$2001="Pass")) -> 53 | C6: =IF(B5=0,"",B6/B5) -> 0.68831169
A7: Failed | B7: =SUMPRODUCT(--('DOE Status'!$B$1:$B$2001="STATUS UNIT"),--('DOE Status'!$H$1:$H$2001="Fail"))+SUMPRODUCT(--('DOE Status'!$B$1:$B$2001="STATUS UNIT"),--('DOE Status'!$I$1:$I$2001="Fail"))+SUMPRODUCT(--('DOE Status'!$B$1:$B$2001="STATUS UNIT"),--('DOE Status'!$J$1:$J$2001="Fail"))+SUMPRODUCT(--('DOE Status'!$B$1:$B$2001="STATUS UNIT"),--('DOE Status'!$K$1:$K$2001="Fail")) -> 13 | C7: =IF(B5=0,"",B7/B5) -> 0.16883117
A8: Damage | B8: =SUMPRODUCT(--('DOE Status'!$B$1:$B$2001="STATUS UNIT"),--('DOE Status'!$H$1:$H$2001="Damage"))+SUMPRODUCT(--('DOE Status'!$B$1:$B$2001="STATUS UNIT"),--('DOE Status'!$I$1:$I$2001="Damage"))+SUMPRODUCT(--('DOE Status'!$B$1:$B$2001="STATUS UNIT"),--('DOE Status'!$J$1:$J$2001="Damage"))+SUMPRODUCT(--('DOE Status'!$B$1:$B$2001="STATUS UNIT"),--('DOE Status'!$K$1:$K$2001="Damage")) -> 11 | C8: =IF(B5=0,"",B8/B5) -> 0.14285714
A9: Pending / not final | B9: =SUMPRODUCT(--('DOE Status'!$B$1:$B$2001="STATUS UNIT"),--('DOE Status'!$H$1:$H$2001=""))+SUMPRODUCT(--('DOE Status'!$B$1:$B$2001="STATUS UNIT"),--('DOE Status'!$I$1:$I$2001=""))+SUMPRODUCT(--('DOE Status'!$B$1:$B$2001="STATUS UNIT"),--('DOE Status'!$J$1:$J$2001=""))+SUMPRODUCT(--('DOE Status'!$B$1:$B$2001="STATUS UNIT"),--('DOE Status'!$K$1:$K$2001="")) -> 3 | D9: Waiting to test / In progress / Need to retest / blank

Sheet Calc_SM3.5
A1: SM3.5 STATUS UNIT Values (linked)
A2: Row | B2: Column | C2: Cell | D2: Value | F2: Counts | I2: MSN Values (non-empty counted) | J2: Total MSN (non-empty)
A3: 8 | B3: G | C3: Sheet1!G8 | D3: ='DOE Status'!H8 -> Pass | F3: Pass | G3: =COUNTIF(D3:D51,"Pass") -> 25 | I3: MSN | J3: 11
A4: 8 | B4: H | C4: Sheet1!H8 | D4: ='DOE Status'!I8 -> Pass | F4: Fail | G4: =COUNTIF(D3:D51,"Fail") -> 8 | I4: ='DOE Status'!C3 -> 56A30400
A5: 8 | B5: I | C5: Sheet1!I8 | D5: ='DOE Status'!J8 -> Pass | F5: Damage | G5: =COUNTIF(D3:D51,"Damage") -> 9 | I5: ='DOE Status'!C12 -> 56A08BF1
A6: 8 | B6: J | C6: Sheet1!J8 | D6: ='DOE Status'!K8 -> Damage | F6: Pending/Other | G6: =COUNTA(D3:D51)-SUM(G3:G5) -> 6 | I6: ='DOE Status'!C21 -> 56A079D4
A7: 17 | B7: G | C7: Sheet1!G17 | D7: ='DOE Status'!H17 -> Pass | F7: Total Tested | G7: =SUM(G3:G5) -> 42 | I7: ='DOE Status'!C30 -> 56A079A4
A8: 17 | B8: H | C8: Sheet1!H17 | D8: ='DOE Status'!I17 -> Pass | I8: ='DOE Status'!C39 -> 569F1C57
A9: 17 | B9: I | C9: Sheet1!I17 | D9: ='DOE Status'!J17 -> Pass | I9: ='DOE Status'!#REF! -> #REF!
A10: 17 | B10: J | C10: Sheet1!J17 | D10: ='DOE Status'!K17 -> Fail | I10: ='DOE Status'!C48 -> 569F1D2F
A11: 26 | B11: G | C11: Sheet1!G26 | D11: ='DOE Status'!H26 -> Pass | I11: ='DOE Status'!C57 -> 56A07A05
A12: 26 | B12: H | C12: Sheet1!H26 | D12: ='DOE Status'!I26 -> Pass | I12: ='DOE Status'!C66 -> 56A47403
A13: 26 | B13: I | C13: Sheet1!I26 | D13: ='DOE Status'!J26 -> Pass | I13: ='DOE Status'!C75 -> 56A05337
A14: 26 | B14: J | C14: Sheet1!J26 | D14: ='DOE Status'!K26 -> Damage | I14: ='DOE Status'!C84 -> 569F1E00
A15: 35 | B15: G | C15: Sheet1!G35 | D15: ='DOE Status'!H35 -> Damage
A16: 35 | B16: H | C16: Sheet1!H35 | D16: ='DOE Status'!I35 -> Fail
A17: 35 | B17: I | C17: Sheet1!I35 | D17: ='DOE Status'!J35 -> Fail
A18: 35 | B18: J | C18: Sheet1!J35 | D18: ='DOE Status'!K35 -> Fail
A19: 44 | B19: G | C19: Sheet1!G44 | D19: ='DOE Status'!H44 -> Pass
A20: 44 | B20: H | C20: Sheet1!H44 | D20: ='DOE Status'!I44 -> Pass
A21: 44 | B21: I | C21: Sheet1!I44 | D21: ='DOE Status'!J44 -> Damage
A22: 44 | B22: J | C22: Sheet1!J44 | D22: ='DOE Status'!K44 -> Damage
A23: 53 | B23: G | C23: Sheet1!G53 | D23: ='DOE Status'!#REF! -> #REF!
A24: 53 | B24: H | C24: Sheet1!H53 | D24: ='DOE Status'!#REF! -> #REF!
A25: 53 | B25: I | C25: Sheet1!I53 | D25: ='DOE Status'!#REF! -> #REF!
A26: 53 | B26: J | C26: Sheet1!J53 | D26: ='DOE Status'!#REF! -> #REF!
A27: 62 | B27: G | C27: Sheet1!G62 | D27: ='DOE Status'!#REF! -> #REF!
A28: 62 | B28: H | C28: Sheet1!H62 | D28: ='DOE Status'!#REF! -> #REF!
A29: 62 | B29: I | C29: Sheet1!I62 | D29: ='DOE Status'!J53 -> Damage
A30: 62 | B30: J | C30: Sheet1!J62 | D30: ='DOE Status'!K53 -> Pass
A31: 71 | B31: G | C31: Sheet1!G71 | D31: ='DOE Status'!H62 -> Damage
A32: 71 | B32: H | C32: Sheet1!H71 | D32: ='DOE Status'!I62 -> Fail
A33: 71 | B33: I | C33: Sheet1!I71 | D33: ='DOE Status'!J62 -> Damage
A34: 71 | B34: J | C34: Sheet1!J71 | D34: ='DOE Status'!K62 -> Pass
A35: 80 | B35: G | C35: Sheet1!G80 | D35: ='DOE Status'!H53 -> Pass
A36: 80 | B36: H | C36: Sheet1!H80 | D36: ='DOE Status'!I53 -> Pass
A37: 80 | B37: I | C37: Sheet1!I80 | D37: ='DOE Status'!J71 -> Pass
A38: 80 | B38: J | C38: Sheet1!J80 | D38: ='DOE Status'!K71 -> Fail
A39: 89 | B39: G | C39: Sheet1!G89 | D39: ='DOE Status'!H80 -> Pass
A40: 89 | B40: H | C40: Sheet1!H89 | D40: ='DOE Status'!I80 -> Pass
...

Sheet SM3.5 Insights
A1: 📊 DOE STATUS - KEY INSIGHTS DASHBOARD (Including Waiting Test)
A2: Analysis Date: 4/17/2026
A4: 1️⃣ OVERALL PERFORMANCE
A5: Metric | B5: Count | C5: Percentage
A6: Pass | B6: 34 | C6: =B6/B10 -> 0.57627119
A7: Fail | B7: 11 | C7: =B7/B10 -> 0.18644068
A8: Damage | B8: 8 | C8: =B8/B10 -> 0.13559322
A9: Waiting Test | B9: 6 | C9: =B9/B10 -> 0.10169492
A10: Total Units | B10: =SUM(B6:B9) -> 59 | C10: -
A12: 2️⃣ UNIT POSITION ANALYSIS
A13: Unit Position | B13: Pass | C13: Fail | D13: Pass Rate
A14: Unit 1 | B14: 11 | C14: 0 | D14: =B14/SUM(B14:C14) -> 1
A15: Unit 2 | B15: 9 | C15: 2 | D15: =B15/SUM(B15:C15) -> 0.81818182
A16: Unit 3 | B16: 8 | C16: 2 | D16: =B16/SUM(B16:C16) -> 0.8
A17: Unit 4 | B17: 6 | C17: 3 | D17: =B17/SUM(B17:C17) -> 0.66666667
A18: TOTAL | B18: =SUM(B14:B17) -> 34 | C18: =SUM(C14:C17) -> 7 | D18: =B18/SUM(B18:C18) -> 0.82926829
A20: 3️⃣ WEEKLY TREND ANALYSIS
A21: Week | B21: Pass | C21: Fail | D21: Pass Rate
A22: WW13 | B22: 9 | C22: 4 | D22: =B22/SUM(B22:C22) -> 0.69230769
A23: WW14 | B23: 12 | C23: 3 | D23: =B23/SUM(B23:C23) -> 0.8
A24: WW15 | B24: 13 | C24: 0 | D24: =B24/SUM(B24:C24) -> 1
A25: TOTAL | B25: =SUM(B22:B24) -> 34 | C25: =SUM(C22:C24) -> 7 | D25: =B25/SUM(B25:C25) -> 0.82926829
A27: 4️⃣ TEST COMPLETION STATUS
A28: Status | B28: Count | C28: Percentage
A29: Completed (Pass+Fail+Damage) | B29: =B6+B7+B8 -> 53 | C29: =B29/B10 -> 0.89830508
A30: Pending (Waiting Test) | B30: =B9 -> 6 | C30: =B30/B10 -> 0.10169492
A31: Completion Rate | B31: - | C31: =B29/B10 -> 0.89830508
A33: 5️⃣ KEY INSIGHTS & RECOMMENDATIONS
A34: 💡 Insight | B34: Finding | C34: Recommendation
A35: Unit 4 Performance | B35: Lowest pass rate (42.9%) | C35: Investigate fixture/alignment issues
A36: Unit 1 Performance | B36: Highest pass rate (78.6%) | C36: Use as benchmark for other positions
A37: WW15 Improvement | B37: 81.3% pass rate, 0 failures! | C37: Document process changes made
A38: WW14 Damage Spike | B38: 7 damaged units (29.2%) | C38: Review handling procedures
A39: Pending Tests | B39: 6 units (10.2%) waiting | C39: Prioritize completion
A40: Top Failure Mode | B40: VDDQc Lamped Error | C40: Root cause analysis needed

Sheet Python Insights
A1: 📊 DOE STATUS - COMPREHENSIVE INSIGHTS DASHBOARD
A2: Analysis Generated: 04/24/2026 | Data Source: DOE Pivot & Charts | Auto-Refresh: Enabled
A4: 1️⃣ KEY PERFORMANCE METRICS
A5: Metric | B5: Count | C5: Percentage | D5: Target | E5: Status | F5: Visual Progress | G5: Trend
A6: 📦 Total Units Tested | B6: =COUNTA('DOE Pivot & Charts'!E5:E156)-COUNTIF('DOE Pivot & Charts'!E5:E156,"") -> 152 | C6: - | D6: ≥150 | E6: =IF(B6>=150,"✅ On Track","⚠️ In Progress") -> ✅ On Track | F6: =REPT("█",ROUND(B6/15,0))&REPT("░",10-ROUND(B6/15,0)) -> ██████████ | G6: 📊
A7: ✅ Pass | B7: =COUNTIF('DOE Pivot & Charts'!E5:E156,"Pass") -> 98 | C7: =B7/B6 -> 0.64473684 | D7: ≥75% | E7: =IF(C7>=0.75,"✅ Good","⚠️ Below Target") -> ⚠️ Below Target | F7: =REPT("█",ROUND(C7*10,0))&REPT("░",10-ROUND(C7*10,0)) -> ██████░░░░ | G7: 📈
A8: ❌ Fail | B8: =COUNTIF('DOE Pivot & Charts'!E5:E156,"Fail") -> 24 | C8: =B8/B6 -> 0.15789474 | D8: ≤10% | E8: =IF(C8<=0.1,"✅ Good","🔴 High") -> 🔴 High | F8: =REPT("█",ROUND(C8*10,0))&REPT("░",10-ROUND(C8*10,0)) -> ██░░░░░░░░ | G8: ⚠️
A9: 🔧 Damage | B9: =COUNTIF('DOE Pivot & Charts'!E5:E156,"Damage") -> 22 | C9: =B9/B6 -> 0.14473684 | D9: ≤10% | E9: =IF(C9<=0.1,"✅ Good","🟡 Monitor") -> 🟡 Monitor | F9: =REPT("█",ROUND(C9*10,0))&REPT("░",10-ROUND(C9*10,0)) -> █░░░░░░░░░ | G9: 🔧
A10: ⏳ Pending | B10: =COUNTIF('DOE Pivot & Charts'!E5:E156,"Pending") -> 8 | C10: =B10/B6 -> 0.052631579 | D10: 0 | E10: =IF(B10=0,"✅ Complete","⏳ In Progress") -> ⏳ In Progress | F10: =REPT("█",ROUND(C10*10,0))&REPT("░",10-ROUND(C10*10,0)) -> █░░░░░░░░░ | G10: ⏳
A12: 2️⃣ WEEKLY TREND ANALYSIS
A13: Week | B13: Pass | C13: Fail | D13: Damage | E13: Total Tested | F13: Pass Rate | G13: Week Status
A14: WW13 | B14: =COUNTIFS('DOE Pivot & Charts'!A5:A156,"WW13",'DOE Pivot & Charts'!E5:E156,"Pass") -> 18 | C14: =COUNTIFS('DOE Pivot & Charts'!A5:A156,"WW13",'DOE Pivot & Charts'!E5:E156,"Fail") -> 8 | D14: =COUNTIFS('DOE Pivot & Charts'!A5:A156,"WW13",'DOE Pivot & Charts'!E5:E156,"Damage") -> 6 | E14: =B14+C14+D14 -> 32 | F14: =IF(E14>0,B14/E14,0) -> 0.5625 | G14: =IF(F14>=0.8,"🟢 Excellent",IF(F14>=0.6,"🟡 Good","🔴 Needs Improvement")) -> 🔴 Needs Improvement
A15: WW14 | B15: =COUNTIFS('DOE Pivot & Charts'!A5:A156,"WW14",'DOE Pivot & Charts'!E5:E156,"Pass") -> 26 | C15: =COUNTIFS('DOE Pivot & Charts'!A5:A156,"WW14",'DOE Pivot & Charts'!E5:E156,"Fail") -> 8 | D15: =COUNTIFS('DOE Pivot & Charts'!A5:A156,"WW14",'DOE Pivot & Charts'!E5:E156,"Damage") -> 14 | E15: =B15+C15+D15 -> 48 | F15: =IF(E15>0,B15/E15,0) -> 0.54166667 | G15: =IF(F15>=0.8,"🟢 Excellent",IF(F15>=0.6,"🟡 Good","🔴 Needs Improvement")) -> 🔴 Needs Improvement
A16: WW15 | B16: =COUNTIFS('DOE Pivot & Charts'!A5:A156,"WW15",'DOE Pivot & Charts'!E5:E156,"Pass") -> 29 | C16: =COUNTIFS('DOE Pivot & Charts'!A5:A156,"WW15",'DOE Pivot & Charts'!E5:E156,"Fail") -> 1 | D16: =COUNTIFS('DOE Pivot & Charts'!A5:A156,"WW15",'DOE Pivot & Charts'!E5:E156,"Damage") -> 2 | E16: =B16+C16+D16 -> 32 | F16: =IF(E16>0,B16/E16,0) -> 0.90625 | G16: =IF(F16>=0.8,"🟢 Excellent",IF(F16>=0.6,"🟡 Good","🔴 Needs Improvement")) -> 🟢 Excellent
A17: WW16 | B17: =COUNTIFS('DOE Pivot & Charts'!A5:A156,"WW16",'DOE Pivot & Charts'!E5:E156,"Pass") -> 25 | C17: =COUNTIFS('DOE Pivot & Charts'!A5:A156,"WW16",'DOE Pivot & Charts'!E5:E156,"Fail") -> 7 | D17: =COUNTIFS('DOE Pivot & Charts'!A5:A156,"WW16",'DOE Pivot & Charts'!E5:E156,"Damage") -> 0 | E17: =B17+C17+D17 -> 32 | F17: =IF(E17>0,B17/E17,0) -> 0.78125 | G17: =IF(F17>=0.8,"🟢 Excellent",IF(F17>=0.6,"🟡 Good","🔴 Needs Improvement")) -> 🟡 Good
A18: 📊 TOTAL | B18: =SUM(B14:B17) -> 98 | C18: =SUM(C14:C17) -> 24 | D18: =SUM(D14:D17) -> 22 | E18: =SUM(E14:E17) -> 144 | F18: =IF(E18>0,B18/E18,0) -> 0.68055556 | G18: 📊 Overall
A20: 3️⃣ UNIT POSITION ANALYSIS
A21: Unit Position | B21: Pass | C21: Fail | D21: Damage | E21: Total | F21: Pass Rate | G21: Status
A22: Unit 1 | B22: =COUNTIFS('DOE Pivot & Charts'!D5:D156,"Unit 1",'DOE Pivot & Charts'!E5:E156,"Pass") -> 28 | C22: =COUNTIFS('DOE Pivot & Charts'!D5:D156,"Unit 1",'DOE Pivot & Charts'!E5:E156,"Fail") -> 4 | D22: =COUNTIFS('DOE Pivot & Charts'!D5:D156,"Unit 1",'DOE Pivot & Charts'!E5:E156,"Damage") -> 4 | E22: =B22+C22+D22 -> 36 | F22: =IF(E22>0,B22/E22,0) -> 0.77777778 | G22: =IF(F22>=0.75,"🟢 Best",IF(F22>=0.6,"🟡 Good","🔴 Needs Focus")) -> 🟢 Best
A23: Unit 2 | B23: =COUNTIFS('DOE Pivot & Charts'!D5:D156,"Unit 2",'DOE Pivot & Charts'!E5:E156,"Pass") -> 26 | C23: =COUNTIFS('DOE Pivot & Charts'!D5:D156,"Unit 2",'DOE Pivot & Charts'!E5:E156,"Fail") -> 6 | D23: =COUNTIFS('DOE Pivot & Charts'!D5:D156,"Unit 2",'DOE Pivot & Charts'!E5:E156,"Damage") -> 4 | E23: =B23+C23+D23 -> 36 | F23: =IF(E23>0,B23/E23,0) -> 0.72222222 | G23: =IF(F23>=0.75,"🟢 Best",IF(F23>=0.6,"🟡 Good","🔴 Needs Focus")) -> 🟡 Good
A24: Unit 3 | B24: =COUNTIFS('DOE Pivot & Charts'!D5:D156,"Unit 3",'DOE Pivot & Charts'!E5:E156,"Pass") -> 23 | C24: =COUNTIFS('DOE Pivot & Charts'!D5:D156,"Unit 3",'DOE Pivot & Charts'!E5:E156,"Fail") -> 7 | D24: =COUNTIFS('DOE Pivot & Charts'!D5:D156,"Unit 3",'DOE Pivot & Charts'!E5:E156,"Damage") -> 6 | E24: =B24+C24+D24 -> 36 | F24: =IF(E24>0,B24/E24,0) -> 0.63888889 | G24: =IF(F24>=0.75,"🟢 Best",IF(F24>=0.6,"🟡 Good","🔴 Needs Focus")) -> 🟡 Good
A25: Unit 4 | B25: =COUNTIFS('DOE Pivot & Charts'!D5:D156,"Unit 4",'DOE Pivot & Charts'!E5:E156,"Pass") -> 21 | C25: =COUNTIFS('DOE Pivot & Charts'!D5:D156,"Unit 4",'DOE Pivot & Charts'!E5:E156,"Fail") -> 7 | D25: =COUNTIFS('DOE Pivot & Charts'!D5:D156,"Unit 4",'DOE Pivot & Charts'!E5:E156,"Damage") -> 8 | E25: =B25+C25+D25 -> 36 | F25: =IF(E25>0,B25/E25,0) -> 0.58333333 | G25: =IF(F25>=0.75,"🟢 Best",IF(F25>=0.6,"🟡 Good","🔴 Needs Focus")) -> 🔴 Needs Focus
A26: 📊 TOTAL | B26: =SUM(B22:B25) -> 98 | C26: =SUM(C22:C25) -> 24 | D26: =SUM(D22:D25) -> 22 | E26: =SUM(E22:E25) -> 144 | F26: =IF(E26>0,B26/E26,0) -> 0.68055556 | G26: 📊 Average
A28: 4️⃣ PRODUCT COMPARISON (Merlin vs SM3.5)
A29: Product | B29: Pass | C29: Fail | D29: Damage | E29: Total | F29: Pass Rate | G29: Performance
A30: Merlin | B30: =COUNTIFS('DOE Pivot & Charts'!C5:C156,"Merlin",'DOE Pivot & Charts'!E5:E156,"Pass") -> 53 | C30: =COUNTIFS('DOE Pivot & Charts'!C5:C156,"Merlin",'DOE Pivot & Charts'!E5:E156,"Fail") -> 12 | D30: =COUNTIFS('DOE Pivot & Charts'!C5:C156,"Merlin",'DOE Pivot & Charts'!E5:E156,"Damage") -> 11 | E30: =B30+C30+D30 -> 76 | F30: =IF(E30>0,B30/E30,0) -> 0.69736842 | G30: =IF(F30>=0.75,"🟢 Excellent",IF(F30>=0.6,"🟡 Good","🔴 Below Target")) -> 🟡 Good
A31: SM3.5 | B31: =COUNTIFS('DOE Pivot & Charts'!C5:C156,"SM3.5",'DOE Pivot & Charts'!E5:E156,"Pass") -> 45 | C31: =COUNTIFS('DOE Pivot & Charts'!C5:C156,"SM3.5",'DOE Pivot & Charts'!E5:E156,"Fail") -> 12 | D31: =COUNTIFS('DOE Pivot & Charts'!C5:C156,"SM3.5",'DOE Pivot & Charts'!E5:E156,"Damage") -> 11 | E31: =B31+C31+D31 -> 68 | F31: =IF(E31>0,B31/E31,0) -> 0.66176471 | G31: =IF(F31>=0.75,"🟢 Excellent",IF(F31>=0.6,"🟡 Good","🔴 Below Target")) -> 🟡 Good
A32: 📊 TOTAL | B32: =SUM(B30:B31) -> 98 | C32: =SUM(C30:C31) -> 24 | D32: =SUM(D30:D31) -> 22 | E32: =SUM(E30:E31) -> 144 | F32: =IF(E32>0,B32/E32,0) -> 0.68055556 | G32: 📊 Combined
A34: 5️⃣ WEEKLY UNIT PASS RATE BREAKDOWN (Cross-Tab Analysis)
A35: Week | B35: Unit 1 | C35: Unit 2 | D35: Unit 3 | E35: Unit 4 | F35: Week Avg
A36: WW13 | B36: =IFERROR(COUNTIFS('DOE Pivot & Charts'!A5:A156,"WW13",'DOE Pivot & Charts'!D5:D156,"Unit 1",'DOE Pivot & Charts'!E5:E156,"Pass")/COUNTIFS('DOE Pivot & Charts'!A5:A156,"WW13",'DOE Pivot & Charts'!D5:D156,"Unit 1",'DOE Pivot & Charts'!E5:E156,"<>"),0) -> 0.75 | C36: =IFERROR(COUNTIFS('DOE Pivot & Charts'!A5:A156,"WW13",'DOE Pivot & Charts'!D5:D156,"Unit 2",'DOE Pivot & Charts'!E5:E156,"Pass")/COUNTIFS('DOE Pivot & Charts'!A5:A156,"WW13",'DOE Pivot & Charts'!D5:D156,"Unit 2",'DOE Pivot & Charts'!E5:E156,"<>"),0) -> 0.75 | D36: =IFERROR(COUNTIFS('DOE Pivot & Charts'!A5:A156,"WW13",'DOE Pivot & Charts'!D5:D156,"Unit 3",'DOE Pivot & Charts'!E5:E156,"Pass")/COUNTIFS('DOE Pivot & Charts'!A5:A156,"WW13",'DOE Pivot & Charts'!D5:D156,"Unit 3",'DOE Pivot & Charts'!E5:E156,"<>"),0) -> 0.75 | E36: =IFERROR(COUNTIFS('DOE Pivot & Charts'!A5:A156,"WW13",'DOE Pivot & Charts'!D5:D156,"Unit 4",'DOE Pivot & Charts'!E5:E156,"Pass")/COUNTIFS('DOE Pivot & Charts'!A5:A156,"WW13",'DOE Pivot & Charts'!D5:D156,"Unit 4",'DOE Pivot & Charts'!E5:E156,"<>"),0) -> 0 | F36: =AVERAGE(B36:E36) -> 0.5625
A37: WW14 | B37: =IFERROR(COUNTIFS('DOE Pivot & Charts'!A5:A156,"WW14",'DOE Pivot & Charts'!D5:D156,"Unit 1",'DOE Pivot & Charts'!E5:E156,"Pass")/COUNTIFS('DOE Pivot & Charts'!A5:A156,"WW14",'DOE Pivot & Charts'!D5:D156,"Unit 1",'DOE Pivot & Charts'!E5:E156,"<>"),0) -> 0.66666667 | C37: =IFERROR(COUNTIFS('DOE Pivot & Charts'!A5:A156,"WW14",'DOE Pivot & Charts'!D5:D156,"Unit 2",'DOE Pivot & Charts'!E5:E156,"Pass")/COUNTIFS('DOE Pivot & Charts'!A5:A156,"WW14",'DOE Pivot & Charts'!D5:D156,"Unit 2",'DOE Pivot & Charts'!E5:E156,"<>"),0) -> 0.66666667 | D37: =IFERROR(COUNTIFS('DOE Pivot & Charts'!A5:A156,"WW14",'DOE Pivot & Charts'!D5:D156,"Unit 3",'DOE Pivot & Charts'!E5:E156,"Pass")/COUNTIFS('DOE Pivot & Charts'!A5:A156,"WW14",'DOE Pivot & Charts'!D5:D156,"Unit 3",'DOE Pivot & Charts'!E5:E156,"<>"),0) -> 0.33333333 | E37: =IFERROR(COUNTIFS('DOE Pivot & Charts'!A5:A156,"WW14",'DOE Pivot & Charts'!D5:D156,"Unit 4",'DOE Pivot & Charts'!E5:E156,"Pass")/COUNTIFS('DOE Pivot & Charts'!A5:A156,"WW14",'DOE Pivot & Charts'!D5:D156,"Unit 4",'DOE Pivot & Charts'!E5:E156,"<>"),0) -> 0.5 | F37: =AVERAGE(B37:E37) -> 0.54166667
A38: WW15 | B38: =IFERROR(COUNTIFS('DOE Pivot & Charts'!A5:A156,"WW15",'DOE Pivot & Charts'!D5:D156,"Unit 1",'DOE Pivot & Charts'!E5:E156,"Pass")/COUNTIFS('DOE Pivot & Charts'!A5:A156,"WW15",'DOE Pivot & Charts'!D5:D156,"Unit 1",'DOE Pivot & Charts'!E5:E156,"<>"),0) -> 1 | C38: =IFERROR(COUNTIFS('DOE Pivot & Charts'!A5:A156,"WW15",'DOE Pivot & Charts'!D5:D156,"Unit 2",'DOE Pivot & Charts'!E5:E156,"Pass")/COUNTIFS('DOE Pivot & Charts'!A5:A156,"WW15",'DOE Pivot & Charts'!D5:D156,"Unit 2",'DOE Pivot & Charts'!E5:E156,"<>"),0) -> 0.75 | D38: =IFERROR(COUNTIFS('DOE Pivot & Charts'!A5:A156,"WW15",'DOE Pivot & Charts'!D5:D156,"Unit 3",'DOE Pivot & Charts'!E5:E156,"Pass")/COUNTIFS('DOE Pivot & Charts'!A5:A156,"WW15",'DOE Pivot & Charts'!D5:D156,"Unit 3",'DOE Pivot & Charts'!E5:E156,"<>"),0) -> 1 | E38: =IFERROR(COUNTIFS('DOE Pivot & Charts'!A5:A156,"WW15",'DOE Pivot & Charts'!D5:D156,"Unit 4",'DOE Pivot & Charts'!E5:E156,"Pass")/COUNTIFS('DOE Pivot & Charts'!A5:A156,"WW15",'DOE Pivot & Charts'!D5:D156,"Unit 4",'DOE Pivot & Charts'!E5:E156,"<>"),0) -> 0.875 | F38: =AVERAGE(B38:E38) -> 0.90625
A39: WW16 | B39: =IFERROR(COUNTIFS('DOE Pivot & Charts'!A5:A156,"WW16",'DOE Pivot & Charts'!D5:D156,"Unit 1",'DOE Pivot & Charts'!E5:E156,"Pass")/COUNTIFS('DOE Pivot & Charts'!A5:A156,"WW16",'DOE Pivot & Charts'!D5:D156,"Unit 1",'DOE Pivot & Charts'!E5:E156,"<>"),0) -> 0.6 | C39: =IFERROR(COUNTIFS('DOE Pivot & Charts'!A5:A156,"WW16",'DOE Pivot & Charts'!D5:D156,"Unit 2",'DOE Pivot & Charts'!E5:E156,"Pass")/COUNTIFS('DOE Pivot & Charts'!A5:A156,"WW16",'DOE Pivot & Charts'!D5:D156,"Unit 2",'DOE Pivot & Charts'!E5:E156,"<>"),0) -> 0.6 | D39: =IFERROR(COUNTIFS('DOE Pivot & Charts'!A5:A156,"WW16",'DOE Pivot & Charts'!D5:D156,"Unit 3",'DOE Pivot & Charts'!E5:E156,"Pass")/COUNTIFS('DOE Pivot & Charts'!A5:A156,"WW16",'DOE Pivot & Charts'!D5:D156,"Unit 3",'DOE Pivot & Charts'!E5:E156,"<>"),0) -> 0.5 | E39: =IFERROR(COUNTIFS('DOE Pivot & Charts'!A5:A156,"WW16",'DOE Pivot & Charts'!D5:D156,"Unit 4",'DOE Pivot & Charts'!E5:E156,"Pass")/COUNTIFS('DOE Pivot & Charts'!A5:A156,"WW16",'DOE Pivot & Charts'!D5:D156,"Unit 4",'DOE Pivot & Charts'!E5:E156,"<>"),0) -> 0.8 | F39: =AVERAGE(B39:E39) -> 0.625
A40: 📊 Unit Avg | B40: =AVERAGE(B36:B39) -> 0.75416667 | C40: =AVERAGE(C36:C39) -> 0.69166667 | D40: =AVERAGE(D36:D39) -> 0.64583333 | E40: =AVERAGE(E36:E39) -> 0.54375 | F40: =AVERAGE(B40:E40) -> 0.65885417
A42: 6️⃣ TREND ANALYSIS - WEEK-OVER-WEEK CHANGE
A43: Week Transition | B43: Previous Rate | C43: Current Rate | D43: Change | E43: Trend | F43: Action
A44: WW13 → WW14 | B44: =F14 -> 0.5625 | C44: =F15 -> 0.54166667 | D44: =C44-B44 -> -0.020833333 | E44: =IF(D44>0.05,"📈 Improving",IF(D44<-0.05,"📉 Declining","➡️ Stable")) -> ➡️ Stable | F44: =IF(D44<-0.05,"⚠️ Investigate","✅ Continue") -> ✅ Continue
A45: WW14 → WW15 | B45: =F15 -> 0.54166667 | C45: =F16 -> 0.90625 | D45: =C45-B45 -> 0.36458333 | E45: =IF(D45>0.05,"📈 Improving",IF(D45<-0.05,"📉 Declining","➡️ Stable")) -> 📈 Improving | F45: =IF(D45<-0.05,"⚠️ Investigate","✅ Continue") -> ✅ Continue
A46: WW15 → WW16 | B46: =F16 -> 0.90625 | C46: =F17 -> 0.78125 | D46: =C46-B46 -> -0.125 | E46: =IF(D46>0.05,"📈 Improving",IF(D46<-0.05,"📉 Declining","➡️ Stable")) -> 📉 Declining | F46: =IF(D46<-0.05,"⚠️ Investigate","✅ Continue") -> ⚠️ Investigate
...

Sheet DOE Pivot & Charts
A1: 📊 DOE STATUS — PivotTables & Charts Summary
A2: Generated: 4/22/2026, 8:03:35 PM
H3: 📌 Summary 1: Overall Status (Count of Units)
A4: Week | B4: MSN | C4: Product | D4: Unit | E4: Status | F4: Remark | H4: Status | I4: Merlin | J4: SM3.5 | K4: Total
A5: WW13 | B5: 56A30400 | C5: Merlin | D5: Unit 1 | E5: Pass | H5: Pass | I5: =COUNTIFS(DOE_Flat[Product],"Merlin",DOE_Flat[Status],$H5) -> 53 | J5: =COUNTIFS(DOE_Flat[Product],"SM3.5",DOE_Flat[Status],$H5) -> 45 | K5: =SUM(I5:J5) -> 98
A6: WW13 | B6: 56A30400 | C6: SM3.5 | D6: Unit 1 | E6: Pass | H6: Fail | I6: =COUNTIFS(DOE_Flat[Product],"Merlin",DOE_Flat[Status],$H6) -> 12 | J6: =COUNTIFS(DOE_Flat[Product],"SM3.5",DOE_Flat[Status],$H6) -> 12 | K6: =SUM(I6:J6) -> 24
A7: WW13 | B7: 56A30400 | C7: Merlin | D7: Unit 2 | E7: Pass | H7: Damage | I7: =COUNTIFS(DOE_Flat[Product],"Merlin",DOE_Flat[Status],$H7) -> 11 | J7: =COUNTIFS(DOE_Flat[Product],"SM3.5",DOE_Flat[Status],$H7) -> 11 | K7: =SUM(I7:J7) -> 22
A8: WW13 | B8: 56A30400 | C8: SM3.5 | D8: Unit 2 | E8: Pass | H8: Pending | I8: =COUNTIFS(DOE_Flat[Product],"Merlin",DOE_Flat[Status],$H8) -> 0 | J8: =COUNTIFS(DOE_Flat[Product],"SM3.5",DOE_Flat[Status],$H8) -> 8 | K8: =SUM(I8:J8) -> 8
A9: WW13 | B9: 56A30400 | C9: Merlin | D9: Unit 3 | E9: Pass
A10: WW13 | B10: 56A30400 | C10: SM3.5 | D10: Unit 3 | E10: Pass
A11: WW13 | B11: 56A30400 | C11: Merlin | D11: Unit 4 | E11: Damage | H11: TOTAL | I11: =SUM(I5:I10) -> 76 | J11: =SUM(J5:J10) -> 76 | K11: =SUM(K5:K10) -> 152
A12: WW13 | B12: 56A30400 | C12: SM3.5 | D12: Unit 4 | E12: Damage
A13: WW13 | B13: 56A08BF1 | C13: Merlin | D13: Unit 1 | E13: Pass
A14: WW13 | B14: 56A08BF1 | C14: SM3.5 | D14: Unit 1 | E14: Pass | H14: 📌 Summary 2: Weekly Trend (All Products)
A15: WW13 | B15: 56A08BF1 | C15: Merlin | D15: Unit 2 | E15: Pass | H15: Week | I15: Pass | J15: Fail | K15: Damage | L15: Tested | M15: Pass Rate
A16: WW13 | B16: 56A08BF1 | C16: SM3.5 | D16: Unit 2 | E16: Pass | H16: WW13 | I16: =COUNTIFS(DOE_Flat[Week],$H16,DOE_Flat[Status],"Pass") -> 18 | J16: =COUNTIFS(DOE_Flat[Week],$H16,DOE_Flat[Status],"Fail") -> 8 | K16: =COUNTIFS(DOE_Flat[Week],$H16,DOE_Flat[Status],"Damage") -> 6 | L16: =SUM(I16:K16) -> 32 | M16: =IFERROR(I16/L16,0) -> 0.5625
A17: WW13 | B17: 56A08BF1 | C17: Merlin | D17: Unit 3 | E17: Pass | H17: WW14 | I17: =COUNTIFS(DOE_Flat[Week],$H17,DOE_Flat[Status],"Pass") -> 26 | J17: =COUNTIFS(DOE_Flat[Week],$H17,DOE_Flat[Status],"Fail") -> 8 | K17: =COUNTIFS(DOE_Flat[Week],$H17,DOE_Flat[Status],"Damage") -> 14 | L17: =SUM(I17:K17) -> 48 | M17: =IFERROR(I17/L17,0) -> 0.54166667
A18: WW13 | B18: 56A08BF1 | C18: SM3.5 | D18: Unit 3 | E18: Pass | H18: WW15 | I18: =COUNTIFS(DOE_Flat[Week],$H18,DOE_Flat[Status],"Pass") -> 29 | J18: =COUNTIFS(DOE_Flat[Week],$H18,DOE_Flat[Status],"Fail") -> 1 | K18: =COUNTIFS(DOE_Flat[Week],$H18,DOE_Flat[Status],"Damage") -> 2 | L18: =SUM(I18:K18) -> 32 | M18: =IFERROR(I18/L18,0) -> 0.90625
A19: WW13 | B19: 56A08BF1 | C19: Merlin | D19: Unit 4 | E19: Fail | H19: WW16 | I19: =COUNTIFS(DOE_Flat[Week],$H19,DOE_Flat[Status],"Pass") -> 25 | J19: =COUNTIFS(DOE_Flat[Week],$H19,DOE_Flat[Status],"Fail") -> 7 | K19: =COUNTIFS(DOE_Flat[Week],$H19,DOE_Flat[Status],"Damage") -> 0 | L19: =SUM(I19:K19) -> 32 | M19: =IFERROR(I19/L19,0) -> 0.78125
A20: WW13 | B20: 56A08BF1 | C20: SM3.5 | D20: Unit 4 | E20: Fail | H20: TOTAL | I20: =SUM(I16:I19) -> 98 | J20: =SUM(J16:J19) -> 24 | K20: =SUM(K16:K19) -> 22 | L20: =SUM(L16:L19) -> 144 | M20: =IFERROR(I20/L20,0) -> 0.68055556
A21: WW13 | B21: 56A079D4 | C21: Merlin | D21: Unit 1 | E21: Pass
A22: WW13 | B22: 56A079D4 | C22: SM3.5 | D22: Unit 1 | E22: Pass
A23: WW13 | B23: 56A079D4 | C23: Merlin | D23: Unit 2 | E23: Pass | H23: 📌 Summary 3: Pass Rate by Unit Position (Per Product)
A24: WW13 | B24: 56A079D4 | C24: SM3.5 | D24: Unit 2 | E24: Pass | H24: Unit | I24: Merlin Tested | J24: Merlin Pass | K24: Merlin Pass Rate | L24: SM3.5 Tested | M24: SM3.5 Pass | N24: SM3.5 Pass Rate
A25: WW13 | B25: 56A079D4 | C25: Merlin | D25: Unit 3 | E25: Pass | H25: Unit 1 | I25: =COUNTIFS(DOE_Flat[Product],"Merlin",DOE_Flat[Unit],$H25,DOE_Flat[Status],"Pass")+COUNTIFS(DOE_Flat[Product],"Merlin",DOE_Flat[Unit],$H25,DOE_Flat[Status],"Fail")+COUNTIFS(DOE_Flat[Product],"Merlin",DOE_Flat[Unit],$H25,DOE_Flat[Status],"Damage") -> 19 | J25: =COUNTIFS(DOE_Flat[Product],"Merlin",DOE_Flat[Unit],$H25,DOE_Flat[Status],"Pass") -> 15 | K25: =IFERROR(J25/I25,0) -> 0.78947368 | L25: =COUNTIFS(DOE_Flat[Product],"SM3.5",DOE_Flat[Unit],$H25,DOE_Flat[Status],"Pass")+COUNTIFS(DOE_Flat[Product],"SM3.5",DOE_Flat[Unit],$H25,DOE_Flat[Status],"Fail")+COUNTIFS(DOE_Flat[Product],"SM3.5",DOE_Flat[Unit],$H25,DOE_Flat[Status],"Damage") -> 17 | M25: =COUNTIFS(DOE_Flat[Product],"SM3.5",DOE_Flat[Unit],$H25,DOE_Flat[Status],"Pass") -> 13 | N25: =IFERROR(M25/L25,0) -> 0.76470588
A26: WW13 | B26: 56A079D4 | C26: SM3.5 | D26: Unit 3 | E26: Pass | F26: Failed at HSRT Test , need to rework | H26: Unit 2 | I26: =COUNTIFS(DOE_Flat[Product],"Merlin",DOE_Flat[Unit],$H26,DOE_Flat[Status],"Pass")+COUNTIFS(DOE_Flat[Product],"Merlin",DOE_Flat[Unit],$H26,DOE_Flat[Status],"Fail")+COUNTIFS(DOE_Flat[Product],"Merlin",DOE_Flat[Unit],$H26,DOE_Flat[Status],"Damage") -> 19 | J26: =COUNTIFS(DOE_Flat[Product],"Merlin",DOE_Flat[Unit],$H26,DOE_Flat[Status],"Pass") -> 14 | K26: =IFERROR(J26/I26,0) -> 0.73684211 | L26: =COUNTIFS(DOE_Flat[Product],"SM3.5",DOE_Flat[Unit],$H26,DOE_Flat[Status],"Pass")+COUNTIFS(DOE_Flat[Product],"SM3.5",DOE_Flat[Unit],$H26,DOE_Flat[Status],"Fail")+COUNTIFS(DOE_Flat[Product],"SM3.5",DOE_Flat[Unit],$H26,DOE_Flat[Status],"Damage") -> 17 | M26: =COUNTIFS(DOE_Flat[Product],"SM3.5",DOE_Flat[Unit],$H26,DOE_Flat[Status],"Pass") -> 12 | N26: =IFERROR(M26/L26,0) -> 0.70588235
A27: WW13 | B27: 56A079D4 | C27: Merlin | D27: Unit 4 | E27: Damage | F27: VDDQc lamped error | H27: Unit 3 | I27: =COUNTIFS(DOE_Flat[Product],"Merlin",DOE_Flat[Unit],$H27,DOE_Flat[Status],"Pass")+COUNTIFS(DOE_Flat[Product],"Merlin",DOE_Flat[Unit],$H27,DOE_Flat[Status],"Fail")+COUNTIFS(DOE_Flat[Product],"Merlin",DOE_Flat[Unit],$H27,DOE_Flat[Status],"Damage") -> 19 | J27: =COUNTIFS(DOE_Flat[Product],"Merlin",DOE_Flat[Unit],$H27,DOE_Flat[Status],"Pass") -> 12 | K27: =IFERROR(J27/I27,0) -> 0.63157895 | L27: =COUNTIFS(DOE_Flat[Product],"SM3.5",DOE_Flat[Unit],$H27,DOE_Flat[Status],"Pass")+COUNTIFS(DOE_Flat[Product],"SM3.5",DOE_Flat[Unit],$H27,DOE_Flat[Status],"Fail")+COUNTIFS(DOE_Flat[Product],"SM3.5",DOE_Flat[Unit],$H27,DOE_Flat[Status],"Damage") -> 17 | M27: =COUNTIFS(DOE_Flat[Product],"SM3.5",DOE_Flat[Unit],$H27,DOE_Flat[Status],"Pass") -> 11 | N27: =IFERROR(M27/L27,0) -> 0.64705882
A28: WW13 | B28: 56A079D4 | C28: SM3.5 | D28: Unit 4 | E28: Damage | F28: VDDQc lamped error | H28: Unit 4 | I28: =COUNTIFS(DOE_Flat[Product],"Merlin",DOE_Flat[Unit],$H28,DOE_Flat[Status],"Pass")+COUNTIFS(DOE_Flat[Product],"Merlin",DOE_Flat[Unit],$H28,DOE_Flat[Status],"Fail")+COUNTIFS(DOE_Flat[Product],"Merlin",DOE_Flat[Unit],$H28,DOE_Flat[Status],"Damage") -> 19 | J28: =COUNTIFS(DOE_Flat[Product],"Merlin",DOE_Flat[Unit],$H28,DOE_Flat[Status],"Pass") -> 12 | K28: =IFERROR(J28/I28,0) -> 0.63157895 | L28: =COUNTIFS(DOE_Flat[Product],"SM3.5",DOE_Flat[Unit],$H28,DOE_Flat[Status],"Pass")+COUNTIFS(DOE_Flat[Product],"SM3.5",DOE_Flat[Unit],$H28,DOE_Flat[Status],"Fail")+COUNTIFS(DOE_Flat[Product],"SM3.5",DOE_Flat[Unit],$H28,DOE_Flat[Status],"Damage") -> 17 | M28: =COUNTIFS(DOE_Flat[Product],"SM3.5",DOE_Flat[Unit],$H28,DOE_Flat[Status],"Pass") -> 9 | N28: =IFERROR(M28/L28,0) -> 0.52941176
A29: WW13 | B29: 56A079A4 | C29: Merlin | D29: Unit 1 | E29: Damage
A30: WW13 | B30: 56A079A4 | C30: SM3.5 | D30: Unit 1 | E30: Damage
A31: WW13 | B31: 56A079A4 | C31: Merlin | D31: Unit 2 | E31: Fail | H31: Unit | I31: Merlin Pass Rate | J31: SM3.5 Pass Rate
A32: WW13 | B32: 56A079A4 | C32: SM3.5 | D32: Unit 2 | E32: Fail | H32: Unit 1 | I32: =_xlfn.XLOOKUP(H32,$H$25:$H$28,$K$25:$K$28) -> 0.78947368 | J32: =_xlfn.XLOOKUP(H32,$H$25:$H$28,$N$25:$N$28) -> 0.76470588
A33: WW13 | B33: 56A079A4 | C33: Merlin | D33: Unit 3 | E33: Fail | H33: Unit 2 | I33: =_xlfn.XLOOKUP(H33,$H$25:$H$28,$K$25:$K$28) -> 0.73684211 | J33: =_xlfn.XLOOKUP(H33,$H$25:$H$28,$N$25:$N$28) -> 0.70588235
A34: WW13 | B34: 56A079A4 | C34: SM3.5 | D34: Unit 3 | E34: Fail | H34: Unit 3 | I34: =_xlfn.XLOOKUP(H34,$H$25:$H$28,$K$25:$K$28) -> 0.63157895 | J34: =_xlfn.XLOOKUP(H34,$H$25:$H$28,$N$25:$N$28) -> 0.64705882
A35: WW13 | B35: 56A079A4 | C35: Merlin | D35: Unit 4 | E35: Fail | H35: Unit 4 | I35: =_xlfn.XLOOKUP(H35,$H$25:$H$28,$K$25:$K$28) -> 0.63157895 | J35: =_xlfn.XLOOKUP(H35,$H$25:$H$28,$N$25:$N$28) -> 0.52941176
A36: WW13 | B36: 56A079A4 | C36: SM3.5 | D36: Unit 4 | E36: Fail
A37: WW14 | B37: 569F1C57 | C37: Merlin | D37: Unit 1 | E37: Pass
A38: WW14 | B38: 569F1C57 | C38: SM3.5 | D38: Unit 1 | E38: Pass
A39: WW14 | B39: 569F1C57 | C39: Merlin | D39: Unit 2 | E39: Pass | F39: VDDQc lamped error
A40: WW14 | B40: 569F1C57 | C40: SM3.5 | D40: Unit 2 | E40: Pass | F40: VDDQc lamped error
...

Sheet Sheet1
B1: Details | D1: SM3.5 | H1: Percentage Pass Unit
A2: WW13 | C2: MSN | D2: Unit 1 | E2: Unit 2 | F2: Unit 3 | G2: =_xlfn.TEXTBEFORE(D2, " ", 1) & " 4" -> Unit 4 | H2: =COUNTIF(D8:G8,"Pass")*25% -> 0.75
B3: PIN TO PIN | C3: 56A30400 | D3: Pass | E3: Pass | F3: Pass | G3: Damage
B4: IDD | D4: Pass | E4: Pass | F4: Pass | G4: Damage
B5: CONTINUITY | D5: Pass | E5: Pass | F5: Pass | G5: Damage
B6: FID | D6: Pass | E6: Pass | F6: Pass | G6: Damage
B7: HSRT FLOW | D7: Pass | E7: Pass | F7: Pass | G7: Damage
B8: STATUS UNIT | D8: Pass | E8: Pass | F8: Pass | G8: Damage
B9: REMARK
A11: ww13 | C11: MSN | D11: Unit 1 | E11: Unit 2 | F11: Unit 3 | G11: =_xlfn.TEXTBEFORE(D11, " ", 1) & " 4" -> Unit 4 | H11: =COUNTIF(D17:G17,"Pass")*25% -> 0.75
B12: PIN TO PIN | C12: 56A08BF1 | D12: Pass | E12: Pass | F12: Pass | G12: Fail
B13: IDD | D13: Pass | E13: Pass | F13: Pass | G13: Fail
B14: CONTINUITY | D14: Pass | E14: Pass | F14: Pass | G14: Fail
B15: FID | D15: Pass | E15: Pass | F15: Pass | G15: Fail
B16: HSRT FLOW | D16: Pass | E16: Pass | F16: Fail | G16: Fail
B17: STATUS UNIT | D17: Pass | E17: Pass | F17: Pass | G17: Fail
B18: REMARK | F18: Failed at HSRT Test , need to rework | G18: VDDQc lamped error
A20: ww13 | C20: MSN | D20: Unit 1 | E20: Unit 2 | F20: Unit 3 (GM) | G20: Unit 4 (GM) | H20: =COUNTIF(D26:G26,"Pass")*25% -> 0.75
B21: PIN TO PIN | C21: 56A079D4 | D21: Pass | E21: Pass | F21: Pass | G21: Damage
B22: IDD | D22: Pass | E22: Pass | F22: Pass | G22: Damage
B23: CONTINUITY | D23: Pass | E23: Pass | F23: Pass | G23: Damage
B24: FID | D24: Pass | E24: Pass | F24: Pass | G24: Damage
B25: HSRT FLOW | D25: Pass | E25: Pass | F25: Pass | G25: Damage
B26: STATUS UNIT | D26: Pass | E26: Pass | F26: Pass | G26: Damage
B27: REMARK
A29: WW13 | C29: MSN | D29: Unit 1 | E29: Unit 2 | F29: Unit 3 | G29: =_xlfn.TEXTBEFORE(D29, " ", 1) & " 4" -> Unit 4 | H29: =COUNTIF(D35:G35,"Pass")*25% -> 0
B30: PIN TO PIN | C30: 56A079A4 | D30: Damage | E30: Fail | F30: Fail | G30: Fail
B31: IDD | D31: Damage | E31: Fail | F31: Fail | G31: Fail
B32: CONTINUITY | D32: Damage | E32: Fail | F32: Fail | G32: Fail
B33: FID | D33: Damage | E33: Fail | F33: Fail | G33: Fail
B34: HSRT FLOW | D34: Damage | E34: Fail | F34: Fail | G34: Fail
B35: STATUS UNIT | D35: Damage | E35: Fail | F35: Fail | G35: Fail
B36: REMARK | E36: VDDQc lamped error | F36: VDDQc lamped error | G36: VDDQc lamped error
A38: ww14 | C38: MSN | D38: Unit 1 | E38: Unit 2 | F38: Unit 3 | G38: =_xlfn.TEXTBEFORE(D38, " ", 1) & " 4" -> Unit 4 | H38: =COUNTIF(D44:G44,"Pass")*25% -> 0.5
B39: PIN TO PIN | C39: 569F1C57 | D39: Pass | E39: Pass | F39: Damage | G39: Damage
B40: IDD | D40: Pass | E40: Pass | F40: Damage | G40: Damage
B41: CONTINUITY | D41: Pass | E41: Pass | F41: Damage | G41: Damage
B42: FID | D42: Pass | E42: Pass | F42: Damage | G42: Damage
B43: HSRT FLOW | D43: Pass | E43: Pass | F43: Damage | G43: Damage
B44: STATUS UNIT | D44: Pass | E44: Pass | F44: Damage | G44: Damage
...

Sheet Sheet1 Insights
A1: 📊 DOE STATUS - COMPREHENSIVE INSIGHTS DASHBOARD (Sheet1 SM3.5 Data)
A2: Analysis Generated: 04/24/2026 | Data Source: Sheet1 SM3.5 | Auto-Refresh: Enabled
A4: 1️⃣ KEY PERFORMANCE METRICS | I4: Status | J4: Count | P4: Week | Q4: Pass Rate
A5: Metric | B5: Count | C5: Percentage | D5: Target | E5: Status | F5: Visual Progress | G5: Trend | I5: Pass | J5: 52 | P5: WW13 | Q5: 0.5625
A6: 📦 Total Units Tested | B6: 80 | C6: - | D6: ≥60 | E6: ✅ On Track | F6: ██████████ | G6: 📊 | I6: Fail | J6: 13 | P6: WW14 | Q6: 0.5417
A7: ✅ Pass | B7: 52 | C7: =TEXT(B7/76,"0.0%") -> 68.4% | D7: ≥75% | E7: ⚠️ Below Target | F7: ██████░░░░ | G7: 📈 | I7: Damage | J7: 11 | P7: WW15 | Q7: 0.875
A8: ❌ Fail | B8: 13 | C8: =TEXT(B8/76,"0.0%") -> 17.1% | D8: ≤10% | E8: 🔴 High | F8: ██░░░░░░░░ | G8: ⚠️ | I8: Pending | J8: 4 | P8: WW16 | Q8: 0.8
A9: 🔧 Damage | B9: 11 | C9: =TEXT(B9/76,"0.0%") -> 14.5% | D9: ≤10% | E9: 🟡 Monitor | F9: █░░░░░░░░░ | G9: 🔧
A10: ⏳ Pending | B10: 4 | C10: =TEXT(B10/80,"0.0%") -> 5.0% | D10: 0 | E10: ⏳ In Progress | F10: █░░░░░░░░░ | G10: ⏳
A12: 2️⃣ WEEKLY TREND ANALYSIS
A13: Week | B13: Pass | C13: Fail | D13: Damage | E13: Total Tested | F13: Pass Rate | G13: Week Status
A14: WW13 | B14: 9 | C14: 4 | D14: 3 | E14: 16 | F14: =TEXT(B14/E14,"0.0%") -> 56.3% | G14: 🔴 Needs Improvement
A15: WW14 | B15: 13 | C15: 4 | D15: 7 | E15: 24 | F15: =TEXT(B15/E15,"0.0%") -> 54.2% | G15: 🔴 Needs Improvement
A16: WW15 | B16: 14 | C16: 1 | D16: 1 | E16: 16 | F16: =TEXT(B16/E16,"0.0%") -> 87.5% | G16: 🟢 Excellent
A17: WW16 | B17: 16 | C17: 4 | D17: 0 | E17: 20 | F17: =TEXT(B17/E17,"0.0%") -> 80.0% | G17: 🟢 Good
A18: 📊 TOTAL | B18: 52 | C18: 13 | D18: 11 | E18: 76 | F18: =TEXT(B18/E18,"0.0%") -> 68.4% | G18: 📊 Overall
A20: 3️⃣ UNIT POSITION ANALYSIS
A21: Unit Position | B21: Pass | C21: Fail | D21: Damage | E21: Total | F21: Pass Rate | G21: Status
A22: Unit 1 | B22: 15 | C22: 1 | D22: 3 | E22: 19 | F22: =TEXT(B22/E22,"0.0%") -> 78.9% | G22: 🟢 Best
A23: Unit 2 | B23: 13 | C23: 3 | D23: 2 | E23: 18 | F23: =TEXT(B23/E23,"0.0%") -> 72.2% | G23: 🟡 Good
A24: Unit 3 | B24: 13 | C24: 4 | D24: 2 | E24: 19 | F24: =TEXT(B24/E24,"0.0%") -> 68.4% | G24: 🟡 Good | I24: Week | J24: Pass | K24: Fail | L24: Damage | P24: Unit | Q24: Pass Rate | R24: Target
A25: Unit 4 | B25: 11 | C25: 5 | D25: 4 | E25: 20 | F25: =TEXT(B25/E25,"0.0%") -> 55.0% | G25: 🔴 Needs Focus | I25: WW13 | J25: 9 | K25: 4 | L25: 3 | P25: Unit 1 | Q25: 0.789 | R25: 0.75
A26: 📊 TOTAL | B26: 52 | C26: 13 | D26: 11 | E26: 76 | F26: =TEXT(B26/E26,"0.0%") -> 68.4% | G26: 📊 Average | I26: WW14 | J26: 13 | K26: 4 | L26: 7 | P26: Unit 2 | Q26: 0.722 | R26: 0.75
I27: WW15 | J27: 14 | K27: 1 | L27: 1 | P27: Unit 3 | Q27: 0.684 | R27: 0.75
A28: 4️⃣ WEEKLY UNIT PASS RATE BREAKDOWN (Cross-Tab Analysis) | I28: WW16 | J28: 16 | K28: 4 | L28: 0 | P28: Unit 4 | Q28: 0.55 | R28: 0.75
A29: Week | B29: Unit 1 | C29: Unit 2 | D29: Unit 3 | E29: Unit 4 | F29: Week Avg
A30: WW13 | B30: 0.75 | C30: 0.75 | D30: 0.75 | E30: 0 | F30: 0.5625
A31: WW14 | B31: 0.6667 | C31: 0.6667 | D31: 0.3333 | E31: 0.5 | F31: 0.5417
A32: WW15 | B32: 1 | C32: 0.75 | D32: 1 | E32: 0.75 | F32: 0.875
A33: WW16 | B33: 0.8 | C33: 0.75 | D33: 0.6667 | E33: 1 | F33: 0.8042
A34: 📊 Unit Avg | B34: 0.8042 | C34: 0.7292 | D34: 0.6875 | E34: 0.5625 | F34: 0.6958
A36: 5️⃣ WEEK-OVER-WEEK TREND ANALYSIS
A37: Transition | B37: From | C37: To | D37: Change | E37: Direction
A38: WW13 → WW14 | B38: 0.563 | C38: 0.542 | D38: -0.021 | E38: ➡️ Stable
A39: WW14 → WW15 | B39: 0.542 | C39: 0.875 | D39: 0.333 | E39: 📈 Improving
A40: WW15 → WW16 | B40: 0.875 | C40: 0.8 | D40: -0.075 | E40: 📉 Declining
A42: 6️⃣ KEY INSIGHTS & RECOMMENDATIONS
A43: 💡 Insight | B43: Finding | C43: Impact | D43: Action | E43: Priority
A44: 🏆 Best Week | B44: WW15: 87.5% pass rate | C44: High | D44: Document process improvements | E44: 🟡 Medium | I44: Unit | J44: Pass | K44: Fail | L44: Damage | M44: % Pass | P44: Failure Mode | Q44: Count
A45: ⚠️ Unit 4 Issue | B45: 55.0% pass rate (lowest) | C45: High | D45: Check fixture/alignment | E45: 🔴 Critical | I45: Unit 1 | J45: 15 | K45: 1 | L45: 3 | M45: =J45/(SUM(J45:L45)) -> 0.78947368 | N45: =SUM(J45:L45) -> 19 | P45: VDDQc Lamped Error | Q45: 7
...
